Workbook
Name Slicer_AccountName: #N/A
Name Slicer_Date___Copy: #N/A
Name Slicer_Department: #N/A
Name Slicer_Type: #N/A

Sheet Report
B3: Actual vs Budget
B5: Final exam
B7: 1. Executive Summary
B8: Sales & Marketing massively exceeded budget — with a variance of ~$3.89M (the largest of any department), driven heavily by the Sales account line which alone totaled ~$159.9M actual vs. a $79M budget, meaning the department spent roughly 104.71% over budget.
B10: Most expense categories ran over budget — Cost of Sales (–$33.5M), Salaries (–$25.8M), and Commissions (–$6.1M) were the biggest negative variances, suggesting widespread cost overruns rather than isolated incidents.
B12: Four departments stayed under budget — Finance (+$256K), General & Administration (+$770K), Operations (+$610K), and Sales & Marketing (+$3.89M) all show positive variances, totaling a $5.52M favorable grand total variance, meaning the company is actually ahead overall despite departmental overruns.
B14: Revenue is highly seasonal — Monthly actuals show clear peaks in April ($7.4M), May ($6.7M), and October ($14.8M), with softer months in February and June, suggesting demand is concentrated in specific periods.
B16: Main Recommendation: Investigate the Sales & Marketing department's cost structure immediately — its budget was set at roughly half of actual spend, indicating either a serious budgeting miscalibration or an unplanned surge in sales activity. If the latter, align future budgets to reflect realistic sales-driven cost levels, particularly for Cost of Sales and Commissions, which scale directly with revenue.
B19: 2. Business Questions
B20: "Which department made the biggest change?" — explicitly labeled in the top pivot table, comparing Amount_Budget vs. Amount_Actual across departments like Sales & Marketing, Account, Corporate, Finance, and others.
B22: "Which Top 5 Account Names drove the most variance?" — the bottom-left pivot ranks accounts by variance and sum of amount, highlighting Cost of Sales, Salaries, Telephone, and Commissions as the heaviest negative contributors.
B24: "Which month is bigger/different in spend?" — the labeled monthly comparison table (rows 35–47) directly answers this by showing Amount_Actual vs. Amount_Budget for every month Jan–Dec, revealing October as the peak outlier at $14.8M actual.
... B30: 3. Key KPIs
B31: 📌 Total Actual vs Budget: | E31: $82.7M actual / $79M budget (+$3.7M variance)
B32: 📌 Budget Achievement Rate: | E32: 1.0471
B33: 📌 Largest Department Variance: | E33: Sales & Marketing +$3.89M
B34: 📌 Top Negative Account: | E34: Cost of Sales –$33.46M
B35: 📌 Peak Month by Actual Spend: | E35: October at $14.83M
B36: 📌 Actual_Total Sales | E36: 159872424
B38: Date of Amount
B39: It visualizes performance variances month-to-month, highlighting significant spikes in actual spending during July and October, as well as months where actual spending fell significantly below the budget, such as June and August.
B42: 📊 [Insert Chart: Bar Chart — Revenue by Region]
B54: ✍️ Insight: Explain which region leads, by how much, and what could explain the difference.
B56: Department with Amount of Actual&Budget
B57: It compares the negative financial impact of various administrative and project-related departments against the positive revenue or performance contribution of the "Sales &..." category.
B73: Departmental Contribution to Total Performance.
B74: This analysis is intended to evaluate financial performance efficiency by measuring the variances between projected targets and actual outcomes. The charts and accompanying table highlight performance volatility, specifically identifying months where actual results significantly deviated from the budget—such as the notable surges observed in July and October versus the under-performance in months like June and August.
B92: 7. Recommendations
B93: • Scale Sales & Marketing Spend: Increase budget allocation for "Sales & Marketing". It currently generates the highest actual revenue ($103.7M), making it the primary driver of organizational performance.
B95: •Control High-Variance Expense Categories: Implement a monthly review process for "Salaries" and "Commissions". These represent the largest variances from the budget and significantly impact the overall financial outcome.

Sheet dashboard
C12: =GETPIVOTDATA("[Measures].[actual]",'calculation '!$A$1) -> 82718055 | F12: =GETPIVOTDATA("[Measures].[Budget]",'calculation '!$A$1) -> 79000779 | J12: ='calculation '!C2 -> 3717275.8 | O12: ='calculation '!A4 -> 1.0470537 | T12: =GETPIVOTDATA("[Measures].[Sum of Amount]",'calculation '!$B$3,"[Acount 1].[AccountName]","[Acount 1].[AccountName].&[Sales]") -> 159872424

Sheet calculation 
A1: actual | B1: Budget | C1: Variance | G1: which department make bigger change
A2: 82718055 | B2: 79000779 | C2: 3717275.8
A3: Actual of Budget | B3: Row Labels | C3: Amount_Actual | G3: Department | H3: Amount_Budget | I3: Amount_Actual
A4: =GETPIVOTDATA("[Measures].[actual]",$A$1)/GETPIVOTDATA("[Measures].[Budget]",$A$1) -> 1.0470537 | B4: Sales | C4: 159872424 | G4: Account | H4: -3373888.2 | I4: -3161713
G5: Corporate | H5: -3426187 | I5: -4942350
G6: Finance | H6: -3406790 | I6: -3149941
G7: General and Administration | H7: -3645893 | I7: -2875664
G8: Operations | H8: -3442117 | I8: -2831710
G9: Project | H9: -3547120.8 | I9: -4050364
A10: which Top 5 Account_Name | G10: Sales & Marketing | H10: 99842775 | I10: 103729797
A12: Row Labels | B12: Variance | C12: Sum of Amount
A13: Salaries | B13: -6247161 | C13: -25754842
A14: Conferences | B14: -13485 | C14: -58022 | G14: Department | H14: Variance
A15: Employee Benefits | B15: -472737.75 | C15: -1966364 | G15: Account | H15: 212175.25
A16: Furniture, Fixtures, and Equipment | B16: -28313.25 | C16: -130343 | G16: Corporate | H16: -1516163
A17: Office Supplies | B17: -44011.5 | C17: -236514 | G17: Finance | H17: 256849
A18: Rent | B18: 227068.75 | C18: -154750 | G18: General and Administration | H18: 770229
A19: Telephone | B19: -1179265 | C19: -2208714 | G19: Operations | H19: 610407
A20: Travel | B20: 151644 | C20: -368939 | G20: Project | H20: -503243.25
A21: Utilities | B21: -102126.5 | C21: -502297 | G21: Sales & Marketing | H21: 3887021.8
A22: Vehicles | B22: -65618.75 | C22: -501273 | G22: Grand Total | H22: 3717275.8
A23: Commissions | B23: -5657945 | C23: -6129087
A24: Cost of Sales | B24: -31907518 | C24: -33461754
A25: Discounts | B25: -5256864.5 | C25: -5345940
A26: Marketing Materials | B26: -261558.25 | C26: -285944
A27: Professional Services | B27: 3145.5 | C27: -49586
A28: Sales | B28: 54572022 | C28: 159872424 | F28: Department | G28: Variance
F29: Commissions | G29: -5657945
F30: Conferences | G30: -13485
F31: Cost of Sales | G31: -31907518
F32: Discounts | G32: -5256864.5
A33: which month is bigger in different | F33: Employee Benefits | G33: -472737.75
F34: Furniture, Fixtures, and Equipment | G34: -28313.25
A35: Row Labels | B35: Amount_actual | C35: Amount_Budget | F35: Marketing Materials | G35: -261558.25
A36: Jan | B36: 9923912 | C36: 5869102.7 | F36: Office Supplies | G36: -44011.5
A37: Feb | B37: 6072415 | C37: 5012000.2 | F37: Professional Services | G37: 3145.5
A38: Mar | B38: 7396807 | C38: 5642143.6 | F38: Rent | G38: 227068.75
A39: Apr | B39: 2711694 | C39: 6623501.2 | F39: Salaries | G39: -6247161
A40: May | B40: 6722616 | C40: 5930284.1 | F40: Sales | G40: 54572022
A41: Jun | B41: 715465 | C41: 6726556.9 | F41: Telephone | G41: -1179265
...

Sheet Acount 
A1: AccountCode | B1: AccountName
A2: 2501 | B2: Conferences
A3: 2502 | B3: Employee Benefits
A4: 2505 | B4: Office Supplies
A5: 2507 | B5: Rent
A6: 2508 | B6: Salaries
A7: 2512 | B7: Telephone
A8: 2513 | B8: Travel
A9: 2000 | B9: Cost of Sales
A10: 2514 | B10: Utilities
A11: 2504 | B11: Marketing Materials
A12: 2503 | B12: Furniture, Fixtures, and Equipment
A13: 1000 | B13: Sales
... A17: 2506 | B17: Professional Services

Sheet Type
A1: Type
A2: Actual
A3: Budget

Sheet Department
A1: Department
A2: Operations
A3: Finance
A4: Account
A5: Corporate
A6: General and Administration
A7: Project
A8: Sales & Marketing

Sheet Date
A1: Date | B1: Date - Copy | C1: Date - Copy.1 | D1: Date - Copy.2
A2: 43466 | B2: Jan | C2: 1 | D2: 2019
A3: 43467 | B3: Jan | C3: 1 | D3: 2019
A4: 43468 | B4: Jan | C4: 1 | D4: 2019
A5: 43469 | B5: Jan | C5: 1 | D5: 2019
A6: 43470 | B6: Jan | C6: 1 | D6: 2019
A7: 43471 | B7: Jan | C7: 1 | D7: 2019
A8: 43472 | B8: Jan | C8: 1 | D8: 2019
A9: 43473 | B9: Jan | C9: 1 | D9: 2019
A10: 43474 | B10: Jan | C10: 1 | D10: 2019
A11: 43475 | B11: Jan | C11: 1 | D11: 2019
A12: 43476 | B12: Jan | C12: 1 | D12: 2019
A13: 43477 | B13: Jan | C13: 1 | D13: 2019
... A366: 43830 | B366: Dec | C366: 12 | D366: 2019

Sheet Sheet1
A4: which department make bigger change
A6: Department | B6: =CUBEMEMBER("ThisWorkbookDataModel","[Measures].[Sum of Amount 2]") -> Sum of Amount 2 | C6: =CUBEMEMBER("ThisWorkbookDataModel","[Measures].[Sum of Amount]") -> Sum of Amount
A7: =CUBEMEMBER("ThisWorkbookDataModel","[d_Department].[Department].&[Account]") -> Account | B7: =CUBEVALUE("ThisWorkbookDataModel",$A7,B$6,Slicer_AccountName,Slicer_Date___Copy,Slicer_Type) -> -3373888.2 | C7: =CUBEVALUE("ThisWorkbookDataModel",$A7,C$6,Slicer_AccountName,Slicer_Date___Copy,Slicer_Type) -> -3161713
A8: =CUBEMEMBER("ThisWorkbookDataModel","[d_Department].[Department].&[Corporate]") -> Corporate | B8: =CUBEVALUE("ThisWorkbookDataModel",$A8,B$6,Slicer_AccountName,Slicer_Date___Copy,Slicer_Type) -> -3426187 | C8: =CUBEVALUE("ThisWorkbookDataModel",$A8,C$6,Slicer_AccountName,Slicer_Date___Copy,Slicer_Type) -> -4942350
A9: =CUBEMEMBER("ThisWorkbookDataModel","[d_Department].[Department].&[Finance]") -> Finance | B9: =CUBEVALUE("ThisWorkbookDataModel",$A9,B$6,Slicer_AccountName,Slicer_Date___Copy,Slicer_Type) -> -3406790 | C9: =CUBEVALUE("ThisWorkbookDataModel",$A9,C$6,Slicer_AccountName,Slicer_Date___Copy,Slicer_Type) -> -3149941
A10: =CUBEMEMBER("ThisWorkbookDataModel","[d_Department].[Department].&[General and Administration]") -> General and Administration | B10: =CUBEVALUE("ThisWorkbookDataModel",$A10,B$6,Slicer_AccountName,Slicer_Date___Copy,Slicer_Type) -> -3645893 | C10: =CUBEVALUE("ThisWorkbookDataModel",$A10,C$6,Slicer_AccountName,Slicer_Date___Copy,Slicer_Type) -> -2875664
A11: =CUBEMEMBER("ThisWorkbookDataModel","[d_Department].[Department].&[Operations]") -> Operations | B11: =CUBEVALUE("ThisWorkbookDataModel",$A11,B$6,Slicer_AccountName,Slicer_Date___Copy,Slicer_Type) -> -3442117 | C11: =CUBEVALUE("ThisWorkbookDataModel",$A11,C$6,Slicer_AccountName,Slicer_Date___Copy,Slicer_Type) -> -2831710
A12: =CUBEMEMBER("ThisWorkbookDataModel","[d_Department].[Department].&[Project]") -> Project | B12: =CUBEVALUE("ThisWorkbookDataModel",$A12,B$6,Slicer_AccountName,Slicer_Date___Copy,Slicer_Type) -> -3547120.8 | C12: =CUBEVALUE("ThisWorkbookDataModel",$A12,C$6,Slicer_AccountName,Slicer_Date___Copy,Slicer_Type) -> -4050364 | E12: =CUBEVALUE("ThisWorkbookDataModel","[Measures].[Budget]") -> 79000779
A13: =CUBEMEMBER("ThisWorkbookDataModel","[d_Department].[Department].&[Sales & Marketing]") -> Sales & Marketing | B13: =CUBEVALUE("ThisWorkbookDataModel",$A13,B$6,Slicer_AccountName,Slicer_Date___Copy,Slicer_Type) -> 99842775 | C13: =CUBEVALUE("ThisWorkbookDataModel",$A13,C$6,Slicer_AccountName,Slicer_Date___Copy,Slicer_Type) -> 103729797 | E13: =CUBEVALUE("ThisWorkbookDataModel","[Measures].[actual]","[d_Department].[Department].["&A$13&"]") -> 103729797

Sheet sh

Sheet Refrence
A1: Date | B1: AccountCode | C1: AccountName | D1: Department | E1: Amount | F1: Type
A2: 43466 | B2: 2501 | C2: Conferences | D2: Operations | E2: -165 | F2: Actual
A3: 43466 | B3: 2502 | C3: Employee Benefits | D3: Finance | E3: -4511 | F3: Actual
A4: 43466 | B4: 2502 | C4: Employee Benefits | D4: Operations | E4: -3602 | F4: Actual
A5: 43466 | B5: 2505 | C5: Office Supplies | D5: Account | E5: -529 | F5: Actual
A6: 43466 | B6: 2507 | C6: Rent | D6: Corporate | E6: -2350 | F6: Actual
A7: 43466 | B7: 2507 | C7: Rent | D7: General and Administration | E7: -2040 | F7: Actual
A8: 43466 | B8: 2507 | C8: Rent | D8: Finance | E8: -1940 | F8: Actual
A9: 43466 | B9: 2507 | C9: Rent | D9: Account | E9: -1520 | F9: Actual
A10: 43466 | B10: 2507 | C10: Rent | D10: Operations | E10: -1730 | F10: Actual
A11: 43466 | B11: 2507 | C11: Rent | D11: Project | E11: -1140 | F11: Actual
A12: 43466 | B12: 2508 | C12: Salaries | D12: Operations | E12: -62557 | F12: Actual
A13: 43466 | B13: 2512 | C13: Telephone | D13: Operations | E13: -1794 | F13: Actual
... A5763: 43800 | B5763: 1000 | C5763: Sales | D5763: Sales & Marketing | E5763: 9598172 | F5763: Budget

Sheet Actual
A1: Date | B1: AccountCode | C1: AccountName | D1: Department | E1: Amount
A2: 43466 | B2: 2501 | C2: Conferences | D2: Operations | E2: -165
A3: 43466 | B3: 2502 | C3: Employee Benefits | D3: Finance | E3: -4511
A4: 43466 | B4: 2502 | C4: Employee Benefits | D4: Operations | E4: -3602
A5: 43466 | B5: 2505 | C5: Office Supplies | D5: Account | E5: -529
A6: 43466 | B6: 2507 | C6: Rent | D6: Corporate | E6: -2350
A7: 43466 | B7: 2507 | C7: Rent | D7: General and Administration | E7: -2040
A8: 43466 | B8: 2507 | C8: Rent | D8: Finance | E8: -1940
A9: 43466 | B9: 2507 | C9: Rent | D9: Account | E9: -1520
A10: 43466 | B10: 2507 | C10: Rent | D10: Operations | E10: -1730
A11: 43466 | B11: 2507 | C11: Rent | D11: Project | E11: -1140
A12: 43466 | B12: 2508 | C12: Salaries | D12: Operations | E12: -62557
A13: 43466 | B13: 2512 | C13: Telephone | D13: Operations | E13: -1794
... A4839: 43830 | B4839: 2514 | C4839: Utilities | D4839: Corporate | E4839: -2263

Sheet Budget
A1: Date | B1: AccountCode | C1: AccountName | D1: Department | E1: Amount
A2: Jan 2019 | B2: 2508 | C2: Salaries | D2: General and Administration | E2: -275534.75
A3: Jan 2019 | B3: 2508 | C3: Salaries | D3: Operations | E3: -261651
A4: Jan 2019 | B4: 2508 | C4: Salaries | D4: Corporate | E4: -247981.25
A5: Jan 2019 | B5: 2508 | C5: Salaries | D5: Account | E5: -218538.5
A6: Jan 2019 | B6: 2508 | C6: Salaries | D6: Finance | E6: -210305.75
A7: Jan 2019 | B7: 2508 | C7: Salaries | D7: Sales & Marketing | E7: -184702.25
A8: Jan 2019 | B8: 2508 | C8: Salaries | D8: Project | E8: -184253
A9: Jan 2019 | B9: 2000 | C9: Cost of Sales | D9: Sales & Marketing | E9: -97133.833
A10: Jan 2019 | B10: 2500 | C10: Commissions | D10: Sales & Marketing | E10: -37210.5
A11: Jan 2019 | B11: 2502 | C11: Employee Benefits | D11: Finance | E11: -20462.5
A12: Jan 2019 | B12: 2502 | C12: Employee Benefits | D12: Account | E12: -20240
A13: Jan 2019 | B13: 2512 | C13: Telephone | D13: Account | E13: -19193
... A925: Dec 2019 | B925: 1000 | C925: Sales | D925: Sales & Marketing | E925: 9598172
